<mujoco model="left_hand_link">
    <!-- Base link -->
    <body name="L_paw" pos="0 0 0" euler="1.5707963 0 -1.5707963">
        <geom name="L_paw_geom" type="mesh" mesh="L_paw" rgba="1 1 1 1" mass="0.153951635222705"/>

        <!-- Thumb links and joints -->
        <body name="L_thumb_swing" pos="-0.029178 -0.01525 0.0384">
            <joint name="L_thumb_swing_joint" type="hinge" axis="0 0 1" range="0 2.286" limited="true" damping="0.01"/>
            <geom name="L_thumb_swing_geom" type="mesh" mesh="L_thumb_swing" rgba="0.827450980392157 0.83921568627451 0.827450980392157 1" mass="0.00344766519929713"/>
        
            <body name="L_thumb_1" pos="-0.013367 0.00088357 -0.0052468" euler="1.5708 0 3.0756">
                <joint name="L_thumb_1_joint" type="hinge" axis="0 0 1" range="0 0.78" limited="true" damping="0.01"/>
                <geom name="L_thumb_1_geom" type="mesh" mesh="L_thumb_1" rgba="0.792156862745098 0.819607843137255 0.933333333333333 1" mass="0.0221480762523199"/>
            
                <body name="L_thumb_2" pos="0.0389415822724812 0.0379042246431505 -0.00770000000000043">
                    <joint name="L_thumb_2_joint" type="hinge" axis="0 0 1" range="0 3.14" limited="true" damping="0.01"/>
                    <geom name="L_thumb_2_geom" type="mesh" mesh="L_thumb_2" rgba="0.792156862745098 0.819607843137255 0.933333333333333 1" mass="0.00380031199387229"/>
                
                    <body name="L_thumb_3" pos="0.01728 0.014743 0.0024">
                        <joint name="L_thumb_3_joint" type="hinge" axis="0 0 1" range="0 3.14" limited="true" damping="0.01"/>
                        <geom name="L_thumb_3_geom" type="mesh" mesh="L_thumb_3" rgba="1 1 1 1" mass="0.0067706894584641"/>
                    </body>
                </body>
            </body>
        </body>

        <!-- Index finger links and joints -->
        <body name="L_index_1" pos="-0.034645 0.0059953 0.11967" euler="1.6319 0 -1.5708">
            <joint name="L_index_1_joint" type="hinge" axis="0 0 -1" range="0 1.7" limited="true" damping="0.01"/>
            <geom name="L_index_1_geom" type="mesh" mesh="L_index_1" rgba="0.792156862745098 0.819607843137255 0.933333333333333 1" mass="0.00439457695368253"/>
        
            <body name="L_index_2" pos="-0.00025731 0.032131 -0.001">
                <joint name="L_index_2_joint" type="hinge" axis="0 0 -1" range="0 1.7" limited="true" damping="0.01"/>
                <geom name="L_index_2_geom" type="mesh" mesh="L_index_2" rgba="1 1 1 1" mass="0.00571203807044643"/>
            </body>
        </body>

        <!-- Middle finger links and joints -->
        <body name="L_middle_1" pos="-0.014728 0.0059953 0.1205" euler="1.5708 0 -1.5708">
            <joint name="L_middle_1_joint" type="hinge" axis="0 0 -1" range="0 1.7" limited="true" damping="0.01"/>
            <geom name="L_middle_1_geom" type="mesh" mesh="L_middle_1" rgba="0.792156862745098 0.819607843137255 0.933333333333333 1" mass="0.00439459313596441"/>
        
            <body name="L_middle_2" pos="-0.000257313524408706 0.0321313914917268 -0.000999999999997433">
                <joint name="L_middle_2_joint" type="hinge" axis="0 0 -1" range="0 1.7" limited="true" damping="0.01"/>
                <geom name="L_middle_2_geom" type="mesh" mesh="L_middle_2" rgba="1 1 1 1" mass="0.00621146132075292"/>
            </body>
        </body>

        <!-- Ring finger links and joints -->
        <body name="L_ring_1" pos="0.0060088 0.0059953 0.12031" euler="1.5184 0 -1.5708">
            <joint name="L_ring_1_joint" type="hinge" axis="0 0 -1" range="0 1.7" limited="true" damping="0.01"/>
            <geom name="L_ring_1_geom" type="mesh" mesh="L_ring_1" rgba="0.792156862745098 0.819607843137255 0.933333333333333 1" mass="0.00439459971330683"/>

            <body name="L_ring_2" pos="-0.00025731 0.032131 -0.001">
                <joint name="L_ring_2_joint" type="hinge" axis="0 0 -1" range="0 1.7" limited="true" damping="0.01"/>
                <geom name="L_ring_2_geom" type="mesh" mesh="L_ring_2" rgba="1 1 1 1" mass="0.0062114646816875"/>
            </body>
        </body>

        <!-- pinky finger links and joints -->
        <body name="L_pinky_1" pos="0.026254 0.0059953 0.11901" euler="1.4661 0 -1.5708">
            <joint name="L_pinky_1_joint" type="hinge" axis="0 0 -1" range="0 1.7" limited="true" damping="0.01"/>
            <geom name="L_pinky_1_geom" type="mesh" mesh="L_pinky_1" rgba="0.792156862745098 0.819607843137255 0.933333333333333 1" mass="0.00439465496713926"/>
        
            <body name="L_pinky_2" pos="-0.00025731 0.032131 -0.001">
                <joint name="L_pinky_2_joint" type="hinge" axis="0 0 -1" range="0 1.7" limited="true" damping="0.01"/>
                <geom name="L_pinky_2_geom" type="mesh" mesh="L_pinky_2" rgba="1 1 1 1" mass="0.00441618939121693"/>
            </body>
        </body>
    </body>


</mujoco>
